<?xml version="1.0" encoding="utf-8"?>
<robot name="ranger_mini_v3">
    <link name="base_link">
        <inertial>
            <origin rpy="0 0 0" xyz="-0.0242698272228022 -0.0030308024613212 0.0544267444673498"/>
            <mass value="10"/>
            <inertia ixx="0.1354" ixy="0.0" ixz="0.0" iyy="0.2417" iyz="0.0" izz="0.3085"/>
        </inertial>
        <visual>
            <origin rpy="3.14 0 3.14" xyz="0 0 0.0"/>
            <geometry>
                <mesh filename="src/dream_ros2_bridge/meshes/ranger_mini3.dae"/>
            </geometry>
            <material name="">
                <color rgba="0.792156862745098 0.819607843137255 0.933333333333333 1"/>
            </material>
        </visual>
        <collision>
            <origin rpy="0 0 0" xyz="0 0 -0.1"/>
            <geometry>
                <box size="0.738 0.5 0.24"/>
            </geometry>
        </collision>
    </link>

    <link name="fr_steering_wheel_link">
        <inertial>
            <origin xyz="0.0 0.0 0.0"/>
            <mass value="1"/>
            <inertia ixx="0.01" ixy="0.0" ixz="0.0" iyy="0.01" iyz="0.0" izz="0.01"/>
        </inertial>
        <visual>
            <origin rpy="1.57 0 3.14" xyz="-0.248 -0.113 0.155"/>
            <geometry>
                <mesh filename="src/dream_ros2_bridge/meshes/ranger_mini_v3_wheel_right.dae" />
            </geometry>
            <material name="">
                <color rgba="0.79216 0.81961 0.93333 1"/>
            </material>
        </visual>
        <collision>
            <origin rpy="0 0 0" xyz="0 0 0"/>
            <geometry>
                <cylinder length="0.001" radius="0.001"/>
            </geometry>
        </collision>
    </link>

    <joint name="fr_steering_joint" type="revolute">
        <origin rpy="0 0 0" xyz="0.25 -0.19 -0.1"/>
        <parent link="base_link"/>
        <child link="fr_steering_wheel_link"/>
        <axis rpy="0 0 0" xyz="0 0 -1"/>
        <limit effort="5" lower="-2.1" upper="2.1" velocity="6.28"/>
        <dynamics damping="5.0" friction="0.5"/>
    </joint>

    <link name="fr_wheel_link">
        <inertial>
            <mass value="8"/>
            <origin xyz="0 0 0"/>
            <inertia ixx="0.02047" ixy="0.0" ixz="0.0" iyy="0.02047" iyz="0.0" izz="0.0324"/>
        </inertial>
        <visual>
            <origin rpy="1.57 0 0" xyz="0 0 0"/>
            <geometry>
                <cylinder length="0.06" radius="0.1"/>
            </geometry>
        </visual>
        <collision>
            <origin rpy="1.57 0 0" xyz="0 0 0"/>
            <geometry>
                <cylinder length="0.06" radius="0.1"/>
            </geometry>
        </collision>
    </link>

    <joint name="fr_wheel" type="continuous">
        <origin rpy="0 0 0" xyz="0.0 0.0 -0.12"/>
        <parent link="fr_steering_wheel_link"/>
        <child link="fr_wheel_link"/>
        <axis rpy="0 0 0" xyz="0 1 0"/>
    </joint>

    <link name="rr_steering_wheel_link">
        <inertial>
            <origin xyz="0.0 0.0 0.0"/>
            <mass value="1"/>
            <inertia ixx="0.01" ixy="0.0" ixz="0.0" iyy="0.01" iyz="0.0" izz="0.01"/>
        </inertial>
        <visual>
            <origin rpy="1.57 0 3.14" xyz="-0.248 -0.113 0.155"/>
            <geometry>
                <mesh filename="src/dream_ros2_bridge/meshes/ranger_mini_v3_wheel_right.dae"/>
            </geometry>
            <material name="">
                <color rgba="0.79216 0.81961 0.93333 1"/>
            </material>
        </visual>
        <collision>
            <origin rpy="0 0 0" xyz="0 0 0"/>
            <geometry>
                <cylinder length="0.001" radius="0.001"/>
            </geometry>
        </collision>
    </link>

    <joint name="rr_steering_joint" type="revolute">
        <origin rpy="0 0 0" xyz="-0.25 -0.19 -0.1"/>
        <parent link="base_link"/>
        <child link="rr_steering_wheel_link"/>
        <axis rpy="0 0 0" xyz="0 0 -1"/>
        <limit effort="5" lower="-2.1" upper="2.1" velocity="6.28"/>
        <dynamics damping="5.0" friction="0.5"/>
    </joint>

    <link name="rr_wheel_link">
        <inertial>
            <mass value="8"/>
            <origin xyz="0 0 0"/>
            <inertia ixx="0.02047" ixy="0.0" ixz="0.0" iyy="0.02047" iyz="0.0" izz="0.0324"/>
        </inertial>
        <visual>
            <origin rpy="1.57 0 0" xyz="0 0 0"/>
            <geometry>
                <cylinder length="0.06" radius="0.1"/>
            </geometry>
        </visual>
        <collision>
            <origin rpy="1.57 0 0" xyz="0 0 0"/>
            <geometry>
                <cylinder length="0.06" radius="0.1"/>
            </geometry>
        </collision>
    </link>

    <joint name="rr_wheel" type="continuous">
        <origin rpy="0 0 0" xyz="0.0 0.0 -0.12 "/>
        <parent link="rr_steering_wheel_link"/>
        <child link="rr_wheel_link"/>
        <axis rpy="0 0 0" xyz="0 1 0"/>
    </joint>

    <link name="rl_steering_wheel_link">
        <inertial>
            <origin xyz="0.0 0.0 0.0"/>
            <mass value="1"/>
            <inertia ixx="0.01" ixy="0.0" ixz="0.0" iyy="0.01" iyz="0.0" izz="0.01"/>
        </inertial>
        <visual>
            <origin rpy="1.57 0 3.14" xyz="-0.248 -0.125 -0.192"/>
            <geometry>
                <mesh filename="src/dream_ros2_bridge/meshes/ranger_mini_v3_wheel.dae"/>
            </geometry>
            <material name="">
                <color rgba="0.79216 0.81961 0.93333 1"/>
            </material>
        </visual>
        <collision>
            <origin rpy="0 0 0" xyz="0 0 0"/>
            <geometry>
                <cylinder length="0.001" radius="0.001"/>
            </geometry>
        </collision>
    </link>

    <joint name="rl_steering_joint" type="revolute">
        <origin rpy="0 0 0" xyz="-0.25 0.19 -0.1"/>
        <parent link="base_link"/>
        <child link="rl_steering_wheel_link"/>
        <axis rpy="0 0 0" xyz="0 0 -1"/>
        <limit effort="5" lower="-2.1" upper="2.1" velocity="6.28"/>
        <dynamics damping="5.0" friction="0.5"/>
    </joint>

    <link name="rl_wheel_link">
        <inertial>
            <mass value="8"/>
            <origin xyz="0 0 0"/>
            <inertia ixx="0.02047" ixy="0.0" ixz="0.0" iyy="0.02047" iyz="0.0" izz="0.0324"/>
        </inertial>
        <visual>
            <origin rpy="1.57 0 0" xyz="0 0 0"/>
            <geometry>
                <cylinder length="0.06" radius="0.1"/>
            </geometry>
        </visual>
        <collision>
            <origin rpy="1.57 0 0" xyz="0 0 0"/>
            <geometry>
                <cylinder length="0.06" radius="0.1"/>
            </geometry>
        </collision>
    </link>

    <joint name="rl_wheel" type="continuous">
        <origin rpy="0 0 0" xyz="0.0 0.0 -0.12 "/>
        <parent link="rl_steering_wheel_link"/>
        <child link="rl_wheel_link"/>
        <axis rpy="0 0 0" xyz="0 1 0"/>
    </joint>

    <link name="fl_steering_wheel_link">
        <inertial>
            <origin xyz="0.0 0.0 0.0"/>
            <mass value="1"/>
            <inertia ixx="0.01" ixy="0.0" ixz="0.0" iyy="0.01" iyz="0.0" izz="0.01"/>
        </inertial>
        <visual>
            <origin rpy="1.57 0.0 3.14" xyz="-0.248 -0.125 -0.192"/>
            <geometry>
                <mesh filename="src/dream_ros2_bridge/meshes/ranger_mini_v3_wheel.dae"/>
            </geometry>
            <material name="">
                <color rgba="0.79216 0.81961 0.93333 1"/>
            </material>
        </visual>
        <collision>
            <origin rpy="0 0 0" xyz="0 0 0"/>
            <geometry>
                <cylinder length="0.001" radius="0.001"/>
            </geometry>
        </collision>
    </link>

    <joint name="fl_steering_joint" type="revolute">
        <origin rpy="0 0 0" xyz="0.25 0.19 -0.1"/>
        <parent link="base_link"/>
        <child link="fl_steering_wheel_link"/>
        <axis rpy="0 0 0" xyz="0 0 -1"/>
        <limit effort="5" lower="-2.1" upper="2.1" velocity="6.28"/>
        <dynamics damping="5.0" friction="0.5"/>
    </joint>

    <link name="fl_wheel_link">
        <inertial>
            <mass value="8"/>
            <origin xyz="0 0 0"/>
            <inertia ixx="0.02047" ixy="0.0" ixz="0.0" iyy="0.02047" iyz="0.0" izz="0.0324"/>
        </inertial>
        <visual>
            <origin rpy="1.57 0 0" xyz="0 0 0"/>
            <geometry>
                <cylinder length="0.06" radius="0.1"/>
            </geometry>
        </visual>
        <collision>
            <origin rpy="1.57 0 0" xyz="0 0 0"/>
            <geometry>
                <cylinder length="0.06" radius="0.1"/>
            </geometry>
        </collision>
    </link>

    <joint name="fl_wheel" type="continuous">
        <origin rpy="0 0 0" xyz="0.0 0.0 -0.12"/>
        <parent link="fl_steering_wheel_link"/>
        <child link="fl_wheel_link"/>
        <axis rpy="0 0 0" xyz="0 1 0"/>
    </joint>


    <!-- xarm6 -->
    <link name="arm_base"/>

    <joint name="arm_to_ranger_joint" type="fixed">
        <parent link="arm_base"/>
        <child link="link_base"/>
        <origin rpy="0 0 0" xyz="0 0 0"/>
    </joint>

    <material name="Black">
        <color rgba="0.0 0.0 0.0 1.0"/>
    </material>
    <material name="Red">
        <color rgba="0.8 0.0 0.0 1.0"/>
    </material>
    <material name="White">
        <color rgba="1.0 1.0 1.0 1.0"/>
    </material>
    <material name="Silver">
        <color rgba="0.753 0.753 0.753 1.0"/>
    </material>

    <link name="link_base">
        <inertial>
            <origin rpy="0 0 0" xyz="0.0 0.0 0.09103"/>
            <mass value="2.7"/>
            <inertia ixx="0.00494875" ixy="-3.5E-06" ixz="1.25E-05" iyy="0.00494174" iyz="1.67E-06" izz="0.002219"/>
        </inertial>
        <visual>
            <geometry>
                <mesh filename="src/dream_ros2_bridge/meshes/link_base.stl"/>
            </geometry>
            <origin rpy="0 0 0" xyz="0 0 0"/>
            <material name="White"/>
        </visual>
        <collision>
            <geometry>
                <mesh filename="src/dream_ros2_bridge/meshes/link_base.stl"/>
            </geometry>
            <origin rpy="0 0 0" xyz="0 0 0"/>
        </collision>
    </link>

    <link name="link1">
        <inertial>
            <origin rpy="0 0 0" xyz="0.00022 0.02951 -0.0124"/>
            <mass value="2.3814"/>
            <inertia ixx="0.0058562" ixy="-1.79e-05" ixz="3.55e-06" iyy="0.0050316" iyz="-0.000888336" izz="0.003536652"/>
        </inertial>
        <visual>
            <geometry>
                <mesh filename="src/dream_ros2_bridge/meshes/link1.stl"/>
            </geometry>
            <origin rpy="0 0 0" xyz="0 0 0"/>
            <material name="White"/>
        </visual>
        <collision>
            <geometry>
                <mesh filename="src/dream_ros2_bridge/meshes/link1.stl"/>
            </geometry>
            <origin rpy="0 0 0" xyz="0 0 0"/>
        </collision>
    </link>

    <joint name="joint1" type="revolute">
        <parent link="link_base"/>
        <child link="link1"/>
        <origin rpy="0 0 0" xyz="0 0 0.267"/>
        <axis xyz="0 0 1"/>
        <limit effort="50.0" lower="-6.283185307179586" upper="6.283185307179586" velocity="3.14"/>
        <dynamics damping="1.0" friction="1.0"/>
    </joint>

    <link name="link2">
        <inertial>
            <origin rpy="0 0 0" xyz="0.03881 -0.22783 0.03496"/>
            <mass value="2.2675"/>
            <inertia ixx="0.028315776" ixy="0.005" ixz="0.00066546" iyy="0.0058" iyz="-0.0045741" izz="0.0273447"/>
        </inertial>
        <visual>
            <geometry>
                <mesh filename="src/dream_ros2_bridge/meshes/link2.stl"/>
            </geometry>
            <origin rpy="0 0 0" xyz="0 0 0"/>
            <material name="White"/>
        </visual>
        <collision>
            <geometry>
                <mesh filename="src/dream_ros2_bridge/meshes/link2.stl"/>
            </geometry>
            <origin rpy="0 0 0" xyz="0 0 0"/>
        </collision>
    </link>

    <joint name="joint2" type="revolute">
        <parent link="link1"/>
        <child link="link2"/>
        <origin rpy="-1.5708 0 0" xyz="0 0 0"/>
        <axis xyz="0 0 1"/>
        <limit effort="50.0" lower="-2.059" upper="2.0944" velocity="3.14"/>
        <dynamics damping="1.0" friction="1.0"/>
    </joint>

    <link name="link3">
        <inertial>
            <origin rpy="0 0 0" xyz="0.07041 0.11631 0.0107"/>
            <mass value="1.875"/>
            <inertia ixx="0.0063483" ixy="-0.0015397" ixz="0.00096858" iyy="0.00379758" iyz="0.00186567" izz="0.00595768"/>
        </inertial>
        <visual>
            <geometry>
                <mesh filename="src/dream_ros2_bridge/meshes/link3.stl"/>
            </geometry>
            <origin rpy="0 0 0" xyz="0 0 0"/>
            <material name="White"/>
        </visual>
        <collision>
            <geometry>
                <mesh filename="src/dream_ros2_bridge/meshes/link3.stl"/>
            </geometry>
            <origin rpy="0 0 0" xyz="0 0 0"/>
        </collision>
    </link>

    <joint name="joint3" type="revolute">
        <parent link="link2"/>
        <child link="link3"/>
        <origin rpy="0 0 0" xyz="0.0535 -0.2845 0"/>
        <axis xyz="0 0 1"/>
        <limit effort="32.0" lower="-3.927" upper="0.19198" velocity="3.14"/>
        <dynamics damping="1.0" friction="1.0"/>
    </joint>

    <link name="link4">
        <inertial>
            <origin rpy="0 0 0" xyz="-0.00018 0.01798 -0.02291"/>
            <mass value="1.3192"/>
            <inertia ixx="0.004896" ixy="-6.925e-06" ixz="-1.418e-05" iyy="0.00445694" iyz="-0.00023186" izz="0.00134332"/>
        </inertial>
        <visual>
            <geometry>
                <mesh filename="src/dream_ros2_bridge/meshes/link4.stl"/>
            </geometry>
            <origin rpy="0 0 0" xyz="0 0 0"/>
            <material name="White"/>
        </visual>
        <collision>
            <geometry>
                <mesh filename="src/dream_ros2_bridge/meshes/link4.stl"/>
            </geometry>
            <origin rpy="0 0 0" xyz="0 0 0"/>
        </collision>
    </link>

    <joint name="joint4" type="revolute">
        <parent link="link3"/>
        <child link="link4"/>
        <origin rpy="-1.5708 0 0" xyz="0.0775 0.3425 0"/>
        <axis xyz="0 0 1"/>
        <limit effort="32.0" lower="-6.283185307179586" upper="6.283185307179586" velocity="3.14"/>
        <dynamics damping="1.0" friction="1.0"/>
    </joint>

    <link name="link5">
        <inertial>
            <origin rpy="0 0 0" xyz="0.0651 0.03096 0.00315"/>
            <mass value="1.33854"/>
            <inertia ixx="0.00146378" ixy="-0.000450624" ixz="0.000284306" iyy="0.00184192" iyz="0.000130866" izz="0.002333524"/>
        </inertial>
        <visual>
            <geometry>
                <mesh filename="src/dream_ros2_bridge/meshes/link5.stl"/>
            </geometry>
            <origin rpy="0 0 0" xyz="0 0 0"/>
            <material name="White"/>
        </visual>
        <collision>
            <geometry>
                <mesh filename="src/dream_ros2_bridge/meshes/link5.stl"/>
            </geometry>
            <origin rpy="0 0 0" xyz="0 0 0"/>
        </collision>
    </link>

    <joint name="joint5" type="revolute">
        <parent link="link4"/>
        <child link="link5"/>
        <origin rpy="1.5708 0 0" xyz="0 0 0"/>
        <axis xyz="0 0 1"/>
        <limit effort="32.0" lower="-1.69297" upper="3.141592653589793" velocity="3.14"/>
        <dynamics damping="1.0" friction="1.0"/>
    </joint>

    <link name="link6">
        <inertial>
            <origin rpy="0 0 0" xyz="0 -0.00677 -0.01098"/>
            <mass value="0.17"/>
            <inertia ixx="9.3e-05" ixy="-0.0" ixz="-0.0" iyy="5.87e-05" iyz="-3.6e-06" izz="0.000132"/>
        </inertial>
        <visual>
            <geometry>
                <mesh filename="src/dream_ros2_bridge/meshes/link6.stl"/>
            </geometry>
            <origin rpy="0 0 0" xyz="0 0 0"/>
            <material name="Silver"/>
        </visual>
        <collision>
            <geometry>
                <mesh filename="src/dream_ros2_bridge/meshes/end_tool.stl"/>
            </geometry>
            <origin rpy="0 0 0" xyz="0 0 0"/>
        </collision>
    </link>

    <joint name="joint6" type="revolute">
        <parent link="link5"/>
        <child link="link6"/>
        <origin rpy="-1.5708 0 0" xyz="0.076 0.097 0"/>
        <axis xyz="0 0 1"/>
        <limit effort="20.0" lower="-6.283185307179586" upper="6.283185307179586" velocity="3.14"/>
        <dynamics damping="1.0" friction="1.0"/>
    </joint>

    <link name="link_eef"/>

    <joint name="joint_eef" type="fixed">
        <origin rpy="0 0 0" xyz="0 0 0.172"/>
        <parent link="link6"/>
        <child link="link_eef"/>
    </joint>

    <!-- attach to ranger -->
    <joint name="ranger_with_xarm" type="fixed">
        <origin rpy="0 0 0" xyz="0.1855 0 0.028 "/>
        <parent link="base_link"/>
        <child link="arm_base"/>
    </joint>

</robot>